package chap08;

public class ExceptionEx6 {

	public static void main(String[] args) {
		System.out.println(1);
		System.out.println(2);
		try {
			System.out.println(3);
			System.out.println(0/0);	//	ArithmeticException 을 발생시키지만 이것이 Exception클래스의 자손이므로 catch 가 수행된다.
			System.out.println(4);
		} catch (Exception e) {
			System.out.println(5);
		}
		System.out.println(6);
	}

}
